<?xml version="1.0"?>
<robot name="barista_robot">
        
  <material name="red">
      <color rgba="1.0 0.0 0.0 1"/>
  </material>

  <material name="green_light">
      <color rgba="0.0 1.0 0.0 1"/>
  </material>

  <material name="green_dark">
    <color rgba="0.0 0.5 0.0 1"/>
  </material>

  <material name="blue">
      <color rgba="0.0 0.0 1.0 1"/>
  </material>

  <material name="black">
      <color rgba="0.1 0.1 0.1 1"/>
  </material>

  <material name="grey">
      <color rgba="0.5 0.5 0.5 1"/>
  </material>

  <!-- Body -->
  <link name="base_link">
  </link>
  <joint name="base_link_joint" type="fixed">
    <origin rpy="0 0 0" xyz="0 0 0.1132" />
    <parent link="base_link" />
    <child link="chassis" />
  </joint>
  <link name="chassis">
    <visual>
      <geometry>
          <cylinder length="0.155" radius="0.178"/>
      </geometry>
      <material name="blue"/>
    </visual>
    <collision>
      <geometry>
          <cylinder length="0.155" radius="0.178"/>
      </geometry>
    </collision>
    <inertial>
      <mass value="10."/>
      <origin rpy="0 0 0" xyz="0 0 0"/>
      <inertia ixx="0.009925" ixy="0" ixz="0" iyy="0.009925" iyz="0" izz="0.15842"/>
    </inertial>
  </link>
  <gazebo reference="chassis">
    <kp>1000000000000000000000000000.0</kp>
    <kd>1000000000000000000000000000.0</kd>
    <mu1>1.0</mu1>
    <mu2>1.0</mu2>
    <material>Gazebo/Blue</material>
  </gazebo>

  <!-- Standoff Rods -->
  <joint name="standoff_rods_fl_joint" type="fixed">
    <origin rpy="0 0 0" xyz="0.03 0.13 0.188"/>
    <parent link="chassis" />
    <child link="standoff_rods_fl" />
  </joint>
  <link name="standoff_rods_fl">
    <visual>
      <geometry>
          <cylinder length="0.220" radius="0.01"/>
      </geometry>
      <material name="grey"/>
    </visual>
    <collision>
      <geometry>
          <cylinder length="0.220" radius="0.01"/>
      </geometry>
    </collision>
    <inertial>
      <mass value=".3"/>
      <origin rpy="0 0 0" xyz="0 0 0"/>
      <inertia ixx="0.00121675" ixy="0" ixz="0" iyy="0.00121675" iyz="0" izz="0.000015"/>
    </inertial>
  </link>
  <joint name="standoff_rods_fr_joint" type="fixed">
    <origin rpy="0 0 0" xyz="0.03 -0.13 0.188"/>
    <parent link="chassis" />
    <child link="standoff_rods_fr" />
  </joint>
  <link name="standoff_rods_fr">
    <visual>
      <geometry>
          <cylinder length="0.220" radius="0.01"/>
      </geometry>
      <material name="grey"/>
    </visual>
    <collision>
      <geometry>
          <cylinder length="0.220" radius="0.01"/>
      </geometry>
    </collision>
    <inertial>
      <mass value=".3"/>
      <origin rpy="0 0 0" xyz="0 0 0"/>
      <inertia ixx="0.00121675" ixy="0" ixz="0" iyy="0.00121675" iyz="0" izz="0.000015"/>
    </inertial>
  </link>
  <joint name="standoff_rods_bl_joint" type="fixed">
    <origin rpy="0 0 0" xyz="-0.03 0.13 0.188"/>
    <parent link="chassis" />
    <child link="standoff_rods_bl" />
  </joint>
  <link name="standoff_rods_bl">
    <visual>
      <geometry>
          <cylinder length="0.220" radius="0.01"/>
      </geometry>
      <material name="grey"/>
    </visual>
    <collision>
      <geometry>
          <cylinder length="0.220" radius="0.01"/>
      </geometry>
    </collision>
    <inertial>
      <mass value=".3"/>
      <origin rpy="0 0 0" xyz="0 0 0"/>
      <inertia ixx="0.00121675" ixy="0" ixz="0" iyy="0.00121675" iyz="0" izz="0.000015"/>
    </inertial>
  </link>
  <joint name="standoff_rods_br_joint" type="fixed">
    <origin rpy="0 0 0" xyz="-0.03 -0.13 0.188"/>
    <parent link="chassis" />
    <child link="standoff_rods_br" />
  </joint>
  <link name="standoff_rods_br">
    <visual>
      <geometry>
          <cylinder length="0.220" radius="0.01"/>
      </geometry>
      <material name="grey"/>
    </visual>
    <collision>
      <geometry>
          <cylinder length="0.220" radius="0.01"/>
      </geometry>
    </collision>
    <inertial>
      <mass value=".3"/>
      <origin rpy="0 0 0" xyz="0 0 0"/>
      <inertia ixx="0.00121675" ixy="0" ixz="0" iyy="0.00121675" iyz="0" izz="0.000015"/>
    </inertial>
  </link>
  <gazebo reference="standoff_rods_fr">
    <kp>1000000000000000000000000000.0</kp>
    <kd>1000000000000000000000000000.0</kd>
    <mu1>1.0</mu1>
    <mu2>1.0</mu2>
    <material>Gazebo/Grey</material>
  </gazebo>
  <gazebo reference="standoff_rods_fl">
    <kp>1000000000000000000000000000.0</kp>
    <kd>1000000000000000000000000000.0</kd>
    <mu1>1.0</mu1>
    <mu2>1.0</mu2>
    <material>Gazebo/Grey</material>
  </gazebo>
  <gazebo reference="standoff_rods_br">
    <kp>1000000000000000000000000000.0</kp>
    <kd>1000000000000000000000000000.0</kd>
    <mu1>1.0</mu1>
    <mu2>1.0</mu2>
    <material>Gazebo/Grey</material>
  </gazebo>
  <gazebo reference="standoff_rods_bl">
    <kp>1000000000000000000000000000.0</kp>
    <kd>1000000000000000000000000000.0</kd>
    <mu1>1.0</mu1>
    <mu2>1.0</mu2>
    <material>Gazebo/Grey</material>
  </gazebo>

  <!-- Cup Holder Tray -->
  <joint name="cupholder_tray_joint" type="fixed">
    <origin rpy="0 0 0" xyz="0 0.0 0.343"/>
    <parent link="chassis" />
    <child link="cupholder_tray" />
  </joint>
  <link name="cupholder_tray">
    <visual>
      <geometry>
          <cylinder length="0.09" radius="0.16"/>
      </geometry>
      <material name="blue"/>
    </visual>
    <collision>
      <geometry>
          <cylinder length="0.09" radius="0.16"/>
      </geometry>
    </collision>
    <inertial>
      <mass value="5."/>
      <origin rpy="0 0 0" xyz="0 0 0"/>
      <inertia ixx="0.0102" ixy="0" ixz="0" iyy="0.0102" iyz="0" izz="0.064"/>
    </inertial>
  </link>
  <gazebo reference="cupholder_tray">
    <kp>1000000000000000000000000000.0</kp>
    <kd>1000000000000000000000000000.0</kd>
    <mu1>1.0</mu1>
    <mu2>1.0</mu2>
    <material>Gazebo/Blue</material>
  </gazebo>


  <!-- Wheel Left -->
  <joint name="joint_left_wheel" type="continuous">
    <origin rpy="0 0 0" xyz="-0.05 0.13 -0.078"/>
    <child link="left_wheel"/>
    <parent link="chassis"/>
    <axis rpy="0 0 0" xyz="0 1 0"/>
    <limit effort="10000" velocity="1000"/>
    <joint_properties damping="1.0" friction="1.0"/>
  </joint>
  <link name="left_wheel">
      <visual>
        <origin rpy="0 1.5707 1.5707" xyz="0 0 0"/>
        <geometry>
          <cylinder length="0.02066" radius="0.0352"/>
        </geometry>
        <material name="black"/>
      </visual>
      <collision>
        <origin rpy="0 1.5707 1.5707" xyz="0 0 0"/>
        <geometry>
          <cylinder length="0.0206" radius="0.0352"/>
        </geometry>
      </collision>
      <inertial>
        <origin rpy="0 1.5707 1.5707" xyz="0 0 0"/>
        <mass value="1."/>
        <inertia ixx="0.00061952" ixy="0" ixz="0" iyy="0.00013216" iyz="0" izz="0.00013216"/>
      </inertial>
  </link>
  <gazebo reference="left_wheel">
    <kp>1000000000000000000000000000.0</kp>
    <kd>1000000000000000000000000000.0</kd>
    <mu1>1.0</mu1>
    <mu2>1.0</mu2>
    <material>Gazebo/Black</material>
  </gazebo>


  <!-- Wheel Right -->
  <joint name="joint_right_wheel" type="continuous">
    <origin rpy="0 0 0" xyz="-0.05 -0.13 -0.078"/>
    <child link="right_wheel"/>
    <parent link="chassis"/>
    <axis rpy="0 0 0" xyz="0 1 0"/>
    <limit effort="10000" velocity="1000"/>
    <joint_properties damping="1.0" friction="1.0"/>
  </joint>
  <link name="right_wheel">
      <visual>
        <origin rpy="0 1.5707 1.5707" xyz="0 0 0"/>
        <geometry>
          <cylinder length="0.0206" radius="0.0352"/>
        </geometry>
        <material name="black"/>
      </visual>
      <collision>
        <origin rpy="0 1.5707 1.5707" xyz="0 0 0"/>
        <geometry>
          <cylinder length="0.0206" radius="0.0352"/>
        </geometry>
      </collision>
      <inertial>
        <origin rpy="0 1.5707 1.5707" xyz="0 0 0"/>
        <mass value="1."/>
        <inertia ixx="0.00061952" ixy="0" ixz="0" iyy="0.00013216" iyz="0" izz="0.00013216"/>
      </inertial>
  </link>
  <gazebo reference="right_wheel">
    <kp>1000000000000000000000000000.0</kp>
    <kd>1000000000000000000000000000.0</kd>
    <mu1>1.0</mu1>
    <mu2>1.0</mu2>
    <material>Gazebo/Black</material>
  </gazebo>


  <!-- Caster Wheel Front -->
  <joint name="front_yaw_joint" type="continuous">
    <origin rpy="0 0 0" xyz="0.13 0 -0.078" />
    <parent link="chassis" />
    <child link="front_yaw_link" />
    <axis xyz="0 0 1" />
    <limit effort="1000.0" velocity="100.0" />
    <dynamics damping="0.0" friction="0.1"/>
  </joint>
  <link name="front_yaw_link">
      <visual>
        <origin rpy="0 1.5707 1.5707" xyz="0 0 0"/>
        <geometry>          
          <cylinder length="0.001" radius="0.0352"/>
        </geometry>
        <material name="blue"/>
      </visual>
      <collision>
        <origin rpy="0 1.5707 1.5707" xyz="0 0 0"/>
        <geometry>
          <cylinder length="0.001" radius="0.0352"/>
        </geometry>
      </collision>
      <inertial>
          <origin rpy="0 1.5707 1.5707" xyz="0 0 0"/>
          <mass value="0.05"/>
          <inertia ixx="5.175e-05" ixy="0.0" ixz="0.0" iyy="5.175e-05" iyz="0.0" izz="3.097e-05"/>
      </inertial>
  </link>
  <gazebo reference="front_yaw_link">
      <material>Gazebo/Blue</material>
  </gazebo>

  <joint name="front_roll_joint" type="continuous">
    <origin rpy="0 0 0" xyz="0 0 0" />
    <parent link="front_yaw_link" />
    <child link="front_roll_link" />
    <axis xyz="1 0 0" />
    <limit effort="1000.0" velocity="100.0" />
    <dynamics damping="0.0" friction="0.1"/>
  </joint>
  <link name="front_roll_link">
      <visual>
        <origin rpy="0 1.5707 1.5707" xyz="0 0 0"/>
        <geometry>
          <cylinder length="0.001" radius="0.0352"/>
        </geometry>
        <material name="red"/>
      </visual>
      <collision>
        <origin rpy="0 1.5707 1.5707" xyz="0 0 0"/>
        <geometry>
          <cylinder length="0.001" radius="0.0352"/>
        </geometry>
      </collision>
      <inertial>
          <origin rpy="0 1.5707 1.5707" xyz="0 0 0"/>
          <mass value="0.05"/>
          <inertia ixx="5.175e-05" ixy="0.0" ixz="0.0" iyy="5.175e-05" iyz="0.0" izz="3.097e-05"/>
      </inertial>
  </link>
  <gazebo reference="front_roll_link">
      <material>Gazebo/Red</material>
  </gazebo>

  <joint name="front_pitch_joint" type="continuous">
    <origin rpy="0 0 0" xyz="0 0 0" />
    <parent link="front_roll_link" />
    <child link="front_pitch_link" />
    <axis xyz="0 1 0" />
    <limit effort="1000.0" velocity="100.0" />
    <dynamics damping="0.0" friction="0.1"/>
  </joint>
  <link name="front_pitch_link">
    <visual>
      <origin rpy="0 1.5707 1.5707" xyz="0 0 0"/>
      <geometry>
        <sphere radius="0.0352"/>
      </geometry>
      <material name="green_dark"/>
    </visual>
    <collision>
      <origin rpy="0 1.5707 1.5707" xyz="0 0 0"/>
      <geometry>
        <sphere radius="0.0352"/>
      </geometry>
    </collision>
    <inertial>
        <origin rpy="0 1.5707 1.5707" xyz="0 0 0"/>
        <mass value="1."/>
        <inertia ixx="0.0004952" ixy="0.0" ixz="0.0" iyy="0.0004952" iyz="0.0" izz="0.0004952"/>
    </inertial>
  </link>
  <gazebo reference="front_pitch_link">
    <kp>1000000000000000000000000000.0</kp>
    <kd>1000000000000000000000000000.0</kd>
    <mu1>1.0</mu1>
    <mu2>1.0</mu2>
    <material>Gazebo/Green</material>
  </gazebo>


  <!-- Laser scan -->
  <joint name="joint_laser_scan" type="fixed">
    <origin rpy="0 0 0" xyz="0.11 0 0.1325"/>
    <child link="laser_scan_link"/>
    <parent link="chassis"/>
    <joint_properties damping="1.0" friction="1.0"/>
  </joint>
  <link name="laser_scan_link">
    <visual>
       <origin rpy="0 0 0" xyz="0 0 -0.055"/>
      <geometry>
        <mesh filename="package://barista_robot_description/meshes/sensors/hokuyo_urg_04lx.dae" scale="1.0 1.0 1.0"/>
      </geometry>
    </visual>
    <collision>
       <origin rpy="0 0 0" xyz="0 0 -0.055"/>
      <geometry>
        <box size="0.06 0.06 0.08"/>
      </geometry>
    </collision>
    <inertial>
      <mass value="0.05"/>
      <origin rpy="0 0 0" xyz="0 0 -0.055"/>
      <inertia ixx="1.067e-05" ixy="0" ixz="0" iyy="6.0e-06" iyz="0" izz="1.067e-05"/>
    </inertial>
  </link>
  <gazebo reference="laser_scan_link">
      <sensor name="sensor_ray" type="ray">
          <pose>0 0 0 0 0 0</pose>
          <ray>
            <scan>
              <horizontal>
                <samples>1024</samples>
                <resolution>1.0</resolution>
                <min_angle>-3.14</min_angle>
                <max_angle>3.14</max_angle>
              </horizontal>
            </scan>
            <range>
              <min>0.02</min>
              <max>5.6</max>
            </range>
          </ray>
          <always_on>true</always_on>
          <visualize>true</visualize>
          <update_rate>100.0</update_rate>
          <plugin name="laser" filename="libgazebo_ros_ray_sensor.so">
            <ros>
              <namespace>/barista_robot</namespace>
              <remapping>~/out:=/scan</remapping>
            </ros>
            <output_type>sensor_msgs/LaserScan</output_type>
            <frame_name>laser_scan_link</frame_name>
          </plugin>
      </sensor>
  </gazebo>


  <!-- JOINT PUBLISHER -->
  <gazebo>
    <plugin name="barista_joint_state" filename="libgazebo_ros_joint_state_publisher.so">
      <ros>
          <remapping>~/out:=joint_states</remapping>
      </ros>
      <update_rate>30</update_rate>

      <joint_name>joint_left_wheel</joint_name>
      <joint_name>joint_right_wheel</joint_name>
      <joint_name>front_yaw_joint</joint_name>
      <joint_name>front_roll_joint</joint_name>
      <joint_name>front_pitch_joint</joint_name>
      
    </plugin>
  </gazebo>

  <!-- Differential drive -->
  <gazebo>
    <plugin filename="libgazebo_ros_diff_drive.so" name="differential_drive_controller">

      <!-- wheels -->
      <left_joint>joint_left_wheel</left_joint>
      <right_joint>joint_right_wheel</right_joint>

      <!-- kinematics -->
      <wheel_separation>0.26</wheel_separation>
      <wheel_diameter>0.07</wheel_diameter>

      <!-- limits -->
      <max_wheel_torque>1.0</max_wheel_torque>
      <max_wheel_acceleration>2.0</max_wheel_acceleration>

      <!-- output -->
      <publish_odom>true</publish_odom>
      <publish_odom_tf>true</publish_odom_tf>
      <odometry_frame>odom</odometry_frame>
      <robot_base_frame>base_link</robot_base_frame>

    </plugin>
  </gazebo>

</robot>